<?xml version="1.0" ?>
<!-- =================================================================================== -->
<!-- |    This document was autogenerated by xacro from ./src/cartpole_description/robot/cartpole.urdf.xacro | -->
<!-- |    EDITING THIS FILE BY HAND IS NOT RECOMMENDED                                 | -->
<!-- =================================================================================== -->
<robot name="cart_pole">
  <link name="leg1">
    <visual>
      <geometry>
        <cylinder length="0.5" radius="0.02"/>
      </geometry>
      <origin xyz="0 0 -0.25"/>
      <material name="red"/>
    </visual>
    <collision>
      <geometry>
        <cylinder length="0.5" radius="0.02"/>
      </geometry>
      <origin xyz="0 0 0"/>
    </collision>
    <inertial>
      <mass value="1"/>
      <inertia ixx="0.01" ixy="0.0" ixz="0.0" iyy="0.01" iyz="0.0" izz="0.01"/>
    </inertial>
  </link>
  <link name="leg2">
    <visual>
      <geometry>
        <cylinder length="0.5" radius="0.02"/>
      </geometry>
      <origin xyz="0 0 -0.25"/>
      <material name="red"/>
    </visual>
    <collision>
      <geometry>
        <cylinder length="0.5" radius="0.02"/>
      </geometry>
      <origin xyz="0 0 0"/>
    </collision>
    <inertial>
      <mass value="1"/>
      <inertia ixx="0.01" ixy="0.0" ixz="0.0" iyy="0.01" iyz="0.0" izz="0.01"/>
    </inertial>
  </link>
  <joint name="base_to_leg1" type="fixed">
    <origin xyz="-0.235 0.0 0.0"/>
    <parent link="base_link"/>
    <child link="leg1"/>
  </joint>
  <joint name="base_to_leg2" type="fixed">
    <origin xyz="0.235 0.0 0.0"/>
    <parent link="base_link"/>
    <child link="leg2"/>
  </joint>
  <material name="red">
    <color rgba="1.0 0.0 0.0 1.0"/>
  </material>
  <material name="green">
    <color rgba="0.0 1.0 0.0 1.0"/>
  </material>
  <material name="blue">
    <color rgba="0.0 0.0 1.0 1.0"/>
  </material>
  <material name="gray">
    <color rgba="0.5 0.5 0.5 1.0"/>
  </material>
  <!-- =============== Link & Joint =============== -->
  <!-- Base -->
  <link name="world"/>
  <joint name="base_link_joint" type="fixed">
    <origin xyz="0 0 0.5"/>
    <parent link="world"/>
    <child link="base_link"/>
  </joint>
  <link name="base_link">
    <visual>
      <geometry>
        <box size="0.47 0.05 0.05"/>
      </geometry>
      <origin xyz="0 0 0"/>
      <material name="red"/>
    </visual>
    <collision>
      <geometry>
        <box size="0.47 0.05 0.05"/>
      </geometry>
      <origin xyz="0 0 0"/>
    </collision>
    <inertial>
      <mass value="100"/>
      <inertia ixx="1.0" ixy="0.0" ixz="0.0" iyy="1.0" iyz="0.0" izz="1.0"/>
    </inertial>
  </link>
  <joint name="cart_joint" type="prismatic">
    <origin rpy="0 0 0" xyz="0 0 0.045"/>
    <parent link="base_link"/>
    <child link="cart_link"/>
    <limit effort="30" lower="-0.235" upper="0.235" velocity="10"/>
    <dynamics damping="0.005" friction="0.1"/>
    <axis xyz="1 0 0"/>
  </joint>
  <link name="cart_link">
    <visual>
      <geometry>
        <box size="0.1 0.1 0.04"/>
      </geometry>
      <origin xyz="0 0 0"/>
      <material name="blue"/>
    </visual>
    <collision>
      <geometry>
        <box size="0.1 0.1 0.04"/>
      </geometry>
      <origin xyz="0 0 0"/>
    </collision>
    <inertial>
      <origin xyz="0 0 0"/>
      <mass value="1"/>
      <inertia ixx="0.1" ixy="0.0" ixz="0.0" iyy="0.1" iyz="0.0" izz="0.1"/>
    </inertial>
  </link>
  <joint name="pole_joint" type="revolute">
    <origin rpy="0 3.14159274 0" xyz="0 0.06 0.02"/>
    <parent link="cart_link"/>
    <child link="pole_link"/>
    <limit effort="15" lower="-1.7" upper="1.7" velocity="10"/>
    <dynamics damping="0.00001" friction="0.01"/>
    <axis xyz="0 1 0"/>
  </joint>
  <link name="pole_link">
    <visual>
      <geometry>
        <cylinder length="0.24" radius="0.005"/>
      </geometry>
      <origin xyz="0 0 -0.12"/>
      <material name="green"/>
    </visual>
    <collision>
      <geometry>
        <cylinder length="0.24" radius="0.005"/>
      </geometry>
      <origin xyz="0 0 -0.12"/>
    </collision>
    <inertial>
      <origin xyz="0 0 -0.12"/>
      <mass value="0.1"/>
      <inertia ixx="0.0005" ixy="0.0" ixz="0.0" iyy="0.0005" iyz="0.0" izz="0.00001"/>
    </inertial>
  </link>
  <joint name="tip_joint" type="revolute">
    <origin rpy="0 0 0" xyz="0 0 -0.24"/>
    <parent link="pole_link"/>
    <child link="tip_link"/>
    <limit effort="30" lower="-1.0" upper="1.0" velocity="10"/>
    <dynamics damping="0.005" friction="0.1"/>
    <axis xyz="0 1 0"/>
  </joint>
  <link name="tip_link">
    <inertial>
      <origin xyz="0 0 0"/>
      <mass value="0.0001"/>
      <inertia ixx="0.00000001" ixy="0" ixz="0" iyy="0.00000001" iyz="0" izz="0.00000001"/>
    </inertial>
  </link>
  <!-- =============== Control =============== -->
  <ros2_control type="system">
    <hardware>
      <plugin>gazebo_ros2_control/GazeboSystem</plugin>
    </hardware>
    <joint name="cart_joint">
      <command_interface name="position"/>
      <command_interface name="velocity"/>
      <command_interface name="effort"/>
      <state_interface name="position"/>
      <state_interface name="velocity"/>
      <state_interface name="effort"/>
    </joint>
    <joint name="pole_joint">
      <state_interface name="position"/>
      <state_interface name="velocity"/>
      <state_interface name="effort"/>
    </joint>
  </ros2_control>
  <transmission name="cart_trans">
    <type>transmission_interface/SimpleTransmission</type>
    <joint name="cart_joint">
      <hardwareInterface>hardware_interface/EffortJointInterface</hardwareInterface>
    </joint>
    <actuator name="cart_motor">
      <hardwareInterface>hardware_interface/EffortJointInterface</hardwareInterface>
      <mechanicalReduction>1</mechanicalReduction>
    </actuator>
  </transmission>
  <!-- =============== Gazebo =============== -->
  <gazebo>
    <plugin filename="libgazebo_ros2_control.so" name="gazebo_ros2_control">
      <parameters>/home/emkk/fuzzy_ws/install/cartpole_controller/share/cartpole_controller/config/cartpole_controllers.yaml</parameters>
    </plugin>
  </gazebo>
  <gazebo reference="base_link">
    <selfCollide>false</selfCollide>
    <mu1 value="0.05"/>
    <mu2 value="0.05"/>
  </gazebo>
  <gazebo reference="cart_link">
    <selfCollide>false</selfCollide>
    <mu1 value="1.2"/>
    <mu2 value="1.2"/>
  </gazebo>
  <gazebo reference="pole_link">
    <selfCollide>false</selfCollide>
    <mu1 value="1.2"/>
    <mu2 value="1.2"/>
  </gazebo>
  <gazebo reference="tip_link">
    <selfCollide>false</selfCollide>
    <mu1 value="1.2"/>
    <mu2 value="1.2"/>
  </gazebo>
</robot>
