<?xml version="1.0" ?>
<robot name="cartopole">

  <link name="slideBar">
    <visual>
      <geometry>
        <box size="30 0.05 0.05"/>
      </geometry>
      <origin xyz="0 0 1"/>
    </visual>
    <inertial>
      <mass value="100"/>
      <inertia ixx="1.0" ixy="0.0" ixz="0.0" iyy="1.0" iyz="0.0" izz="1.0"/>
    </inertial>
  </link>

  <link name="cart">
    <visual>
      <geometry>
        <box size="0.5 0.5 0.2"/>
      </geometry>
      <origin xyz="0 0 1"/>
    </visual>
    <inertial>
      <mass value="1"/>
      <inertia ixx="1.0" ixy="0.0" ixz="0.0" iyy="1.0" iyz="0.0" izz="1.0"/>
    </inertial>
  </link>

  <link name="leg1">
    <visual>
      <geometry>
        <cylinder radius="0.2" length="1.0"/>
      </geometry>
      <origin xyz="0 0 0"/>
    </visual>
    <collision>
      <geometry>
        <cylinder radius="0.2" length="1.0"/>
      </geometry>
      <origin xyz="0 0 0"/>
    </collision>
    <inertial>
      <mass value="1"/>
      <inertia ixx="1.0" ixy="0.0" ixz="0.0" iyy="1.0" iyz="0.0" izz="1.0"/>
    </inertial>
  </link>

  <link name="leg2">
    <visual>
      <geometry>
        <cylinder radius="0.2" length="1.0"/>
      </geometry>
      <origin xyz="0 0 0"/>
    </visual>
    <collision>
      <geometry>
        <cylinder radius="0.2" length="1.0"/>
      </geometry>
      <origin xyz="0 0 0"/>
    </collision>
    <inertial>
      <mass value="1"/>
      <inertia ixx="1.0" ixy="0.0" ixz="0.0" iyy="1.0" iyz="0.0" izz="1.0"/>
    </inertial>
  </link>

  <link name="pole">
    <visual>
      <geometry>
        <cylinder radius="0.025" length="1.0"/>
      </geometry>
      <origin xyz="0 0 0.5"/>
    </visual>
    <!-- <collision>
      <geometry>
        <cylinder radius="0.025" length="1.0"/>
      </geometry>
      <origin xyz="0 0 0.5"/>
    </collision> -->
    <inertial>
      <mass value="0.1"/>
      <origin xyz="0 0 0.5"/>
     <inertia 
            ixx="0.083" ixy="0.0" ixz="0.0"
            iyy="0.083" iyz="0.0"
            izz="0.001"/>
    </inertial>
  </link>

  <joint name="slider_to_cart" type="prismatic">
    <axis xyz="1 0 0"/>
    <origin xyz="0.0 0.0 0.0"/>
    <parent link="slideBar"/>
    <child link="cart"/>
    <limit effort="1000.0" lower="-15" upper="15" velocity="200"/>
  </joint>

 <link name="ball">
    <visual>
      <origin xyz="0 0 0" rpy="0 0 0"/>
      <geometry>
        <sphere radius="0.025"/>
      </geometry>
      <material name="red">
        <color rgba="1 0 0 1"/>
      </material>
    </visual>
  </link>
  
  <joint name="slider_to_leg1" type="fixed">
    <origin xyz="-15.0 0.0 0.5"/>
    <parent link="slideBar"/>
    <child link="leg1"/>
    <dynamics damping="0.0" friction="0.0"/>
  </joint>

  <joint name="slider_to_leg2" type="fixed">
    <origin xyz="15 0.0 0.5"/>
    <parent link="slideBar"/>
    <child link="leg2"/>
    <dynamics damping="0.0" friction="0.0"/>
  </joint>

  <joint name="cart_to_pole" type="continuous">
    <parent link="cart"/>
    <child link="pole"/>
    <origin xyz="0 0 1.1"/>
    <axis xyz="0 1 0"/>
    <dynamics damping="0.0" friction="0.0"/>
    <limit effort="1000.0" velocity="1000.0"/> <!-- joint angle max min rad-->
  </joint>

  <joint name="pole_to_ball" type="fixed">
    <origin xyz="0 0 1.0"/>
    <parent link="pole"/>
    <child link="ball"/>
  </joint>

  <ros2_control name="IgnitionSystem" type="system">
    <hardware>
      <plugin>ign_ros2_control/IgnitionSystem</plugin>
    </hardware>
    <joint name="slider_to_cart">
      <command_interface name="effort">
        <param name="min">-15</param>
        <param name="max">15</param>
      </command_interface>
      <state_interface name="position">
        <param name="initial_value">1.0</param>
      </state_interface>
      <state_interface name="velocity"/>
      <state_interface name="effort"/>
    </joint>

    <!-- pole movement joint -->
      <joint name="cart_to_pole">
          <state_interface name="position"/>
          <state_interface name="velocity"/>
          <state_interface name="effort"/>
      </joint>
  </ros2_control>

  <gazebo reference="slideBar">
    <visual>
      <material>
        <ambient>0 0.8 0 1</ambient>
        <diffuse>0 0.8 0 1</diffuse>
        <specular>0 0.8 0 1</specular>
      </material>
    </visual>
  </gazebo>

  <gazebo reference="cart">
    <visual>
      <material>
        <ambient>0 0 0.8 1</ambient>
        <diffuse>0 0 0.8 1</diffuse>
        <specular>0 0 0.8 1</specular>
      </material>
    </visual>
  </gazebo>

  <gazebo reference="pole">
    <visual>
      <material>
        <ambient>1 0 0 1</ambient>
        <diffuse>1 0 0 1</diffuse>
        <specular>1 0 0 1</specular>
      </material>
    </visual>
  </gazebo>

  <gazebo reference="ball">
      <visual>
          <geometry>
              <sphere radius="0.1"/>
          </geometry>
          <material>
              <ambient>1 1 1 1</ambient>
              <diffuse>1 1 1 1</diffuse>
              <specular>1 1 1 1</specular>
          </material>
      </visual>
  </gazebo>

  <gazebo>
    <plugin filename="ign_ros2_control-system" name="ign_ros2_control::IgnitionROS2ControlPlugin">
      <parameters>$(find cartpole_fuzzy)/config/cartpole_controller_effort.yaml</parameters>
    </plugin>
  </gazebo>

</robot>
